Workbook

Sheet A1
A1: APPLE | F1: BRUNELLO CUCINELLI | K1: GOLDMAN SACHS | P1: JP MORGAN | U1: MICROSOFT | Z1: AMERICAN WATER | AE1: PFIZER | AJ1: TOD'S | AO1: RISO | AT1: FIRST SOLAR
A2: Date | B2: Adj Close | D2: Rendimenti attesi | F2: Date | G2: Adj Close | I2: Rendimenti attesi | K2: Date | L2: Adj Close | N2: Rendimenti attesi | P2: Date | Q2: Adj Close | S2: Rendimenti attesi | U2: Date | V2: Adj Close | X2: Rendimenti attesi | Z2: Date | AA2: Adj Close | AC2: Rendimenti attesi | AE2: Date | AF2: Adj Close | AH2: Rendimenti attesi | AJ2: Date | AK2: Adj Close | AM2: Rendimenti attesi | AO2: Date | AP2: Adj Close | AR2: Rendimenti attesi | AT2: Date | AU2: Adj Close | AW2: rendimenti attesi
A3: 41395 | B3: 13872261 | C3: =(B4-B3)/B3 -> -0.11245723 | D3: =AVERAGE(C3:C121) -> 0.024266687 | F3: 41395 | G3: 16363121 | H3: =(G4-G3)/G3 -> 0.098442589 | I3: =AVERAGE(H3:H121) -> 0.018519405 | K3: 41395 | L3: 136430252 | M3: =(L4-L3)/L3 -> -0.063869984 | N3: =AVERAGE(M3:M121) -> 0.010700275 | P3: 41395 | Q3: 41275848 | R3: =(Q4-Q3)/Q3 -> -0.032973181 | S3: =AVERAGE(R3:R121) -> 0.012575794 | U3: 41395 | V3: 28943336 | W3: =(V4-V3)/V3 -> -0.0033754229 | X3: =AVERAGE(W3:W121) -> 0.02125851 | Z3: 41395 | AA3: 32675747 | AB3: =(AA4-AA3)/AA3 -> 0.039113903 | AC3: =AVERAGE(AB3:AB121) -> 0.014317676 | AE3: 41395 | AF3: 18054180 | AG3: =(AF4-AF3)/AF3 -> 0.037219857 | AH3: =AVERAGE(AG3:AG121) -> 0.0088334803 | AJ3: 41395 | AK3: 91764030 | AL3: =(AK4-AK3)/AK3 -> 0.0051930152 | AM3: =AVERAGE(AL3:AL121) -> -0.001530935 | AO3: 41395 | AP3: 838445251 | AQ3: =(AP4-AP3)/AP3 -> 0 | AR3: =AVERAGE(AQ3:AQ121) -> 0.013109003 | AT3: 41395 | AU3: 54389999 | AV3: =(AU4-AU3)/AU3 -> -0.17613529 | AW3: =AVERAGE(AV3:AV121) -> 0.02162117
A4: 41426 | B4: 12312225 | C4: =(B5-B4)/B4 -> 0.14122541 | F4: 41426 | G4: 17973949 | H4: =(G5-G4)/G4 -> 0.072669729 | K4: 41426 | L4: 127716454 | M4: =(L5-L4)/L4 -> 0.084496098 | P4: 41426 | Q4: 39914852 | R4: =(Q5-Q4)/Q4 -> 0.055692102 | U4: 41426 | V4: 28845640 | W4: =(V5-V4)/V4 -> -0.078170184 | Z4: 41426 | AA4: 33953823 | AB4: =(AA5-AA4)/AA4 -> 0.035168234 | AE4: 41426 | AF4: 18726154 | AG4: =(AF5-AF4)/AF4 -> 0.043555553 | AJ4: 41426 | AK4: 92240562 | AL4: =(AK5-AK4)/AK4 -> 0.12707199 | AO4: 41426 | AP4: 838445251 | AQ4: =(AP5-AP4)/AP4 -> -0.018206625 | AT4: 41426 | AU4: 44810001 | AV4: =(AU5-AU4)/AU4 -> 0.09841553
A5: 41456 | B5: 14051024 | C5: =(B6-B5)/B5 -> 0.076658043 | F5: 41456 | G5: 19280111 | H5: =(G6-G5)/G5 -> 0.099656532 | K5: 41456 | L5: 138507996 | M5: =(L6-L5)/L5 -> -0.072547999 | P5: 41456 | Q5: 42137794 | R5: =(Q6-Q5)/Q5 -> -0.086694738 | U5: 41456 | V5: 26590771 | W5: =(V6-V5)/V5 -> 0.048995119 | Z5: 41456 | AA5: 35147919 | AB5: =(AA6-AA5)/AA5 -> -0.045454242 | AE5: 41456 | AF5: 19541782 | AG5: =(AF6-AF5)/AF5 -> -0.027025171 | AJ5: 41456 | AK5: 103961754 | AL5: =(AK6-AK5)/AK5 -> 0.10539218 | AO5: 41456 | AP5: 823179993 | AQ5: =(AP6-AP5)/AP5 -> 0.10755661 | AT5: 41456 | AU5: 49220001 | AV5: =(AU6-AU5)/AU5 -> -0.2539618
A6: 41487 | B6: 15128148 | C6: =(B7-B6)/B6 -> -0.015028475 | F6: 41487 | G6: 21201500 | H6: =(G7-G6)/G6 -> 0.072321345 | K6: 41487 | L6: 128459518 | M6: =(L7-L6)/L6 -> 0.043370831 | P6: 41487 | Q6: 38484669 | R6: =(Q7-Q6)/Q6 -> 0.022956362 | U6: 41487 | V6: 27893589 | W6: =(V7-V6)/V6 -> 0.0034283505 | Z6: 41487 | AA6: 33550297 | AB6: =(AA7-AA6)/AA6 -> 0.020046946 | AE6: 41487 | AF6: 19013662 | AG6: =(AF7-AF6)/AF6 -> 0.01843343 | AJ6: 41487 | AK6: 114918510 | AL6: =(AK7-AK6)/AK6 -> 0.024390153 | AO6: 41487 | AP6: 911718445 | AQ6: =(AP7-AP6)/AP6 -> -0.039346829 | AT6: 41487 | AU6: 36720001 | AV6: =(AU7-AU6)/AU6 -> 0.095043516
A7: 41518 | B7: 14900795 | C7: =(B8-B7)/B7 -> 0.096381904 | F7: 41518 | G7: 22734821 | H7: =(G8-G7)/G7 -> -0.042464596 | K7: 41518 | L7: 134030914 | M7: =(L8-L7)/L7 -> 0.016749718 | P7: 41518 | Q7: 39368137 | R7: =(Q8-Q7)/Q7 -> -0.0029017883 | U7: 41518 | V7: 27989218 | W7: =(V8-V7)/V7 -> 0.064002431 | Z7: 41518 | AA7: 34222878 | AB7: =(AA8-AA7)/AA7 -> 0.038517158 | AE7: 41518 | AF7: 19364149 | AG7: =(AF8-AF7)/AF7 -> 0.068221278 | AJ7: 41518 | AK7: 117721390 | AL7: =(AK8-AK7)/AK7 -> -0.1147187 | AO7: 41518 | AP7: 875845215 | AQ7: =(AP8-AP7)/AP7 -> -0.047494511 | AT7: 41518 | AU7: 40209999 | AV7: =(AU8-AU7)/AU7 -> 0.25118135
A8: 41548 | B8: 16336962 | C8: =(B9-B8)/B8 -> 0.06384149 | F8: 41548 | G8: 21769396 | H8: =(G9-G8)/G8 -> 0.11739141 | K8: 41548 | L8: 136275894 | M8: =(L9-L8)/L8 -> 0.050230226 | P8: 41548 | Q8: 39253899 | R8: =(Q9-Q8)/Q8 -> 0.11838488 | U8: 41548 | V8: 29780596 | W8: =(V9-V8)/V8 -> 0.076814312 | Z8: 41548 | AA8: 35541046 | AB8: =(AA9-AA8)/AA8 -> -0.012129609 | AE8: 41548 | AF8: 20685196 | AG8: =(AF9-AF8)/AF8 -> 0.03388723 | AJ8: 41548 | AK8: 104216545 | AL8: =(AK9-AK8)/AK8 -> 0.015484998 | AO8: 41548 | AP8: 834247375 | AQ8: =(AP9-AP8)/AP8 -> 0.020127948 | AT8: 41548 | AU8: 50310001 | AV8: =(AU9-AU8)/AU8 -> 0.189028
A9: 41579 | B9: 17379938 | C9: =(B10-B9)/B9 -> 0.014792228 | F9: 41579 | G9: 24324936 | H9: =(G10-G9)/G9 -> 0.0050583072 | K9: 41579 | L9: 143121063 | M9: =(L10-L9)/L9 -> 0.052693285 | P9: 41579 | Q9: 43900967 | R9: =(Q10-Q9)/Q9 -> 0.022019948 | U9: 41579 | V9: 32068172 | W9: =(V10-V9)/V9 -> -0.011441469 | Z9: 41579 | AA9: 35109947 | AB9: =(AA10-AA9)/AA9 -> 0.0044662842 | AE9: 41579 | AF9: 21386160 | AG9: =(AF10-AF9)/AF9 -> -0.027193849 | AJ9: 41579 | AK9: 105830338 | AL9: =(AK10-AK9)/AK9 -> -0.025682135 | AO9: 41579 | AP9: 851039063 | AQ9: =(AP10-AP9)/AP9 -> -0.030044916 | AT9: 41579 | AU9: 59820000 | AV9: =(AU10-AU9)/AU9 -> -0.086593129
A10: 41609 | B10: 17637026 | C10: =(B11-B10)/B10 -> -0.10769673 | F10: 41609 | G10: 24447979 | H10: =(G11-G10)/G10 -> -0.21602788 | K10: 41609 | L10: 150662582 | M10: =(L11-L10)/L10 -> -0.074128021 | P10: 41609 | Q10: 44867664 | R10: =(Q11-Q10)/Q10 -> -0.053351318 | U10: 41609 | V10: 31701265 | W10: =(V11-V10)/V10 -> 0.011493642 | Z10: 41609 | AA10: 35266758 | AB10: =(AA11-AA10)/AA10 -> 0.0073354347 | AE10: 41609 | AF10: 20804588 | AG10: =(AF11-AF10)/AF10 -> -0.007509161 | AJ10: 41609 | AK10: 103112389 | AL10: =(AK11-AK10)/AK10 -> -0.16556839 | AO10: 41609 | AP10: 825469666 | AQ10: =(AP11-AP10)/AP10 -> -0.054553682 | AT10: 41609 | AU10: 54639999 | AV10: =(AU11-AU10)/AU10 -> -0.074304485
A11: 41640 | B11: 15737576 | C11: =(B12-B11)/B11 -> 0.051218625 | F11: 41640 | G11: 19166534 | H11: =(G12-G11)/G11 -> 0.0083950494 | K11: 41640 | L11: 139494263 | M11: =(L12-L11)/L11 -> 0.014196942 | P11: 41640 | Q11: 42473915 | R11: =(Q12-Q11)/Q11 -> 0.033085836 | U11: 41640 | V11: 32065628 | W11: =(V12-V11)/V11 -> 0.012420932 | Z11: 41640 | AA11: 35525455 | AB11: =(AA12-AA11)/AA11 -> 0.060400324 | AE11: 41640 | AF11: 20648363 | AG11: =(AF12-AF11)/AF11 -> 0.056250173 | AJ11: 41640 | AK11: 86040237 | AL11: =(AK12-AK11)/AK11 -> -0.02369202 | AO11: 41640 | AP11: 780437256 | AQ11: =(AP12-AP11)/AP11 -> 0.095354433 | AT11: 41640 | AU11: 50580002 | AV11: =(AU12-AU11)/AU11 -> 0.12831154
A12: 41671 | B12: 16543633 | C12: =(B13-B12)/B12 -> 0.026057819 | F12: 41671 | G12: 19327438 | H12: =(G13-G12)/G12 -> -0.059255707 | K12: 41671 | L12: 141474655 | M12: =(L13-L12)/L12 -> -0.012297659 | P12: 41671 | Q12: 43879200 | R12: =(Q13-Q12)/Q12 -> 0.068461686 | U12: 41671 | V12: 32463913 | W12: =(V13-V12)/V12 -> 0.077979078 | Z12: 41671 | AA12: 37671204 | AB12: =(AA13-AA12)/AA12 -> 0.012488637 | AE12: 41671 | AF12: 21809837 | AG12: =(AF13-AF12)/AF12 -> 0.0086526094 | AJ12: 41671 | AK12: 84001770 | AL12: =(AK13-AK12)/AK12 -> -0.047017057 | AO12: 41671 | AP12: 854855408 | AQ12: =(AP13-AP12)/AP12 -> 0.1397321 | AT12: 41671 | AU12: 57070000 | AV12: =(AU13-AU12)/AU12 -> 0.22288419
A13: 41699 | B13: 16974724 | C13: =(B14-B13)/B13 -> 0.099396432 | F13: 41699 | G13: 18182177 | H13: =(G14-G13)/G13 -> 0.077563869 | K13: 41699 | L13: 139734848 | M13: =(L14-L13)/L13 -> -0.024595575 | P13: 41699 | Q13: 46883244 | R13: =(Q14-Q13)/Q13 -> -0.077911524 | U13: 41699 | V13: 34995419 | W13: =(V14-V13)/V13 -> -0.014393884 | Z13: 41699 | AA13: 38141666 | AB13: =(AA14-AA13)/AA13 -> 0.0028632992 | AE13: 41699 | AF13: 21998549 | AG13: =(AF14-AF13)/AF13 -> -0.026151952 | AJ13: 41699 | AK13: 80052254 | AL13: =(AK14-AK13)/AK13 -> 0.070556989 | AO13: 41699 | AP13: 974306152 | AQ13: =(AP14-AP13)/AP13 -> 0.0099087694 | AT13: 41699 | AU13: 69790001 | AV13: =(AU14-AU13)/AU13 -> -0.032956053
A14: 41730 | B14: 18661951 | C14: =(B15-B14)/B14 -> 0.072717585 | F14: 41730 | G14: 19592457 | H14: =(G15-G14)/G14 -> -0.090821228 | K14: 41730 | L14: 136297989 | M14: =(L15-L14)/L14 -> -6.2803568e-05 | P14: 41730 | Q14: 43230499 | R14: =(Q15-Q14)/Q14 -> -0.0010674408 | U14: 41730 | V14: 34491699 | W14: =(V15-V14)/V14 -> 0.013366057 | Z14: 41730 | AA14: 38250877 | AB14: =(AA15-AA14)/AA14 -> 0.067647756 | AE14: 41730 | AF14: 21423244 | AG14: =(AF15-AF14)/AF14 -> -0.052749434 | AJ14: 41730 | AK14: 85700500 | AL14: =(AK15-AK14)/AK14 -> -0.01040645 | AO14: 41730 | AP14: 983960327 | AQ14: =(AP15-AP14)/AP14 -> 0.088270319 | AT14: 41730 | AU14: 67489998 | AV14: =(AU15-AU14)/AU14 -> -0.084605114
A15: 41760 | B15: 20019003 | C15: =(B16-B15)/B15 -> 0.033401713 | F15: 41760 | G15: 17813046 | H15: =(G16-G15)/G15 -> -0.11292982 | K15: 41760 | L15: 136289429 | M15: =(L16-L15)/L15 -> 0.051319072 | P15: 41760 | Q15: 43184353 | R15: =(Q16-Q15)/Q15 -> 0.036890538 | U15: 41760 | V15: 34952717 | W15: =(V16-V15)/V15 -> 0.025749643 | Z15: 41760 | AA15: 40838463 | AB15: =(AA16-AA15)/AA15 -> 0.024046767 | AE15: 41760 | AF15: 20293180 | AG15: =(AF16-AF15)/AF15 -> 0.01061598 | AJ15: 41760 | AK15: 84808662 | AL15: =(AK16-AK15)/AK15 -> -0.0432322 | AO15: 41760 | AP15: 1070814819 | AQ15: =(AP16-AP15)/AP15 -> 0.049689499 | AT15: 41760 | AU15: 61779999 | AV15: =(AU16-AU15)/AU15 -> 0.15021041
... A121: 44986 | B121: 164899994 | C121: =(B122-B121)/B121 -> 0.0018800061 | F121: 44986 | G121: 91449997 | H121: =(G122-G121)/G121 -> 0.01312198 | K121: 44986 | L121: 324784454 | M121: =(L122-L121)/L121 -> 0.037364963 | P121: 44986 | Q121: 129295288 | R121: =(Q122-Q121)/Q121 -> 0.064615123 | U121: 44986 | V121: 288299988 | W121: =(V122-V121)/V121 -> -0.0074921023 | Z121: 44986 | AA121: 146490005 | AB121: =(AA122-AA121)/AA121 -> 0.021912703 | AE121: 44986 | AF121: 40799999 | AG121: =(AF122-AF121)/AF121 -> 0.0095588238 | AJ121: 44986 | AK121: 38160000 | AL121: =(AK122-AK121)/AK121 -> 0.047169785 | AO121: 44986 | AP121: 2210714600 | AQ121: =(AP122-AP121)/AP121 -> 0.036316492 | AT121: 44986 | AU121: 217500000 | AV121: =(AU122-AU121)/AU121 -> -0.0028046023
A122: 45017 | B122: 165210007 | F122: 45017 | G122: 92650002 | K122: 45017 | L122: 336920013 | P122: 45017 | Q122: 137649719 | U122: 45017 | V122: 286140015 | Z122: 45017 | AA122: 149699997 | AE122: 45017 | AF122: 41189999 | AJ122: 45017 | AK122: 39959999 | AO122: 45017 | AP122: 2291000000 | AT122: 45017 | AU122: 216889999
B125: MATRICE VARIANZA COVARIANZA
B126: APPLE | C126: CUCINELLI | D126: GOLDMAN SACHS | E126: JP MORGAN | F126: MICROSOFT | G126: PFIZER | H126: AMERICAN WATER | I126: TOD'S | J126: RISO | K126: FIRST SOLAR
A127: APPLE | B127: =COVAR((C3:C121),(C3:C121)) -> 0.0065193315 | C127: =COVAR(H3:H121,C3:C121) -> 0.0026962466 | D127: =COVAR(M3:M121,C3:C121) -> 0.0027365098 | E127: =COVAR(R3:R121,C3:C121) -> 0.0015093532 | F127: =COVAR(W3:W121,C3:C121) -> 0.0026716787 | G127: =COVAR(AG3:AG121,C3:C121) -> 0.0010845741 | H127: =COVAR(AB3:AB121,C3:C121) -> 0.0008306317 | I127: =COVAR(AL3:AL121,C3:C121) -> 0.0020480484 | J127: =COVAR(AQ3:AQ121,C3:C121) -> 0.0016541391 | K127: =COVAR((C3:C121),(AV3:AV121)) -> 0.0039002786
A128: CUCINELLI | B128: =COVAR(H3:H121,C3:C121) -> 0.0026962466 | C128: =COVAR(H3:H121,H3:H121) -> 0.0079632739 | D128: =COVAR(H3:H121,M3:M121) -> 0.0024359739 | E128: =COVAR(H3:H121,R3:R121) -> 0.0020351704 | F128: =COVAR(W3:W121,H3:H121) -> 0.0018832888 | G128: =COVAR(H3:H121,AG3:AG121) -> 0.0011034986 | H128: =COVAR(H3:H121,AB3:AB121) -> 0.00055703093 | I128: =COVAR(H3:H121,AL3:AL121) -> 0.0036262587 | J128: =COVAR(H3:H121,AQ3:AQ121) -> 0.0019560924 | K128: =COVAR((H3:H121),(AV3:AV121)) -> 0.0013280689
A129: GOLDMAN SACHS | B129: =COVAR(M3:M121,C3:C121) -> 0.0027365098 | C129: =COVAR(M3:M121,H3:H121) -> 0.0024359739 | D129: =COVAR(M3:M121,M3:M121) -> 0.0062094035 | E129: =COVAR(M3:M121,R3:R121) -> 0.0045453646 | F129: =COVAR(M3:M121,W3:W121) -> 0.0019755235 | G129: =COVAR(M3:M121,AG3:AG121) -> 0.0011789993 | H129: =COVAR(M3:M121,AB3:AB121) -> 0.00035617037 | I129: =COVAR(M3:M121,AL3:AL121) -> 0.0020916951 | J129: =COVAR(M3:M121,AQ3:AQ121) -> 0.0017302484 | K129: =COVAR((M3:M121),(AV3:AV121)) -> 0.0029130318
A130: JP MORGAN | B130: =COVAR(R3:R121,C3:C121) -> 0.0015093532 | C130: =COVAR(R3:R121,H3:H121) -> 0.0020351704 | D130: =COVAR(R3:R121,M3:M121) -> 0.0045453646 | E130: =COVAR(R3:R121,R3:R121) -> 0.004803719 | F130: =COVAR(R3:R121,W3:W121) -> 0.0015263099 | G130: =COVAR(R3:R121,AG3:AG121) -> 0.0013561786 | H130: =COVAR(R3:R121,AB3:AB121) -> 0.00020596344 | I130: =COVAR(R3:R121,AL3:AL121) -> 0.00080554605 | J130: =COVAR(R3:R121,AQ3:AQ121) -> 0.0011082172 | K130: =COVAR((R3:R121),(AV3:AV121)) -> 0.0024817366
A131: MICROSOFT | B131: =COVAR(W3:W121,C3:C121) -> 0.0026716787 | C131: =COVAR(W3:W121,H3:H121) -> 0.0018832888 | D131: =COVAR(W3:W121,M3:M121) -> 0.0019755235 | E131: =COVAR(W3:W121,R3:R121) -> 0.0015263099 | F131: =COVAR(W3:W121,W3:W121) -> 0.0037257347 | G131: =COVAR(W3:W121,AG3:AG121) -> 0.00083580321 | H131: =COVAR(W3:W121,AB3:AB121) -> 0.00075067892 | I131: =COVAR(W3:W121,AL3:AL121) -> 0.00067855125 | J131: =COVAR(W3:W121,AQ3:AQ121) -> 0.00088718876 | K131: =COVAR((W3:W121),(AV3:AV121)) -> 0.003476645
A132: PFIZER | B132: =COVAR(AG3:AG121,C3:C121) -> 0.0010845741 | C132: =COVAR(AG3:AG121,H3:H121) -> 0.0011034986 | D132: =COVAR(AG3:AG121,M3:M121) -> 0.0011789993 | E132: =COVAR(AG3:AG121,R3:R121) -> 0.0013561786 | F132: =COVAR(AG3:AG121,W3:W121) -> 0.00083580321 | G132: =COVAR(AG3:AG121,AG3:AG121) -> 0.0038312057 | H132: =COVAR(AG3:AG121,AB3:AB121) -> 0.0012465869 | I132: =COVAR(AG3:AG121,AL3:AL121) -> -6.0479575e-05 | J132: =COVAR(AG3:AG121,AQ3:AQ121) -> -0.00093026099 | K132: =COVAR((AG3:AG121),(AV3:AV121)) -> 0.00059807193
A133: AMERICAN WATER | B133: =COVAR(AB3:AB121,C3:C121) -> 0.0008306317 | C133: =COVAR(AB3:AB121,H3:H121) -> 0.00055703093 | D133: =COVAR(AB3:AB121,M3:M121) -> 0.00035617037 | E133: =COVAR(AB3:AB121,R3:R121) -> 0.00020596344 | F133: =COVAR(AB3:AB121,W3:W121) -> 0.00075067892 | G133: =COVAR(AB3:AB121,AG3:AG121) -> 0.0012465869 | H133: =COVAR(AB3:AB121,AB3:AB121) -> 0.0028918859 | I133: =COVAR(AB3:AB121,AL3:AL121) -> -0.00055982311 | J133: =COVAR(AB3:AB121,AQ3:AQ121) -> -0.00083226071 | K133: =COVAR((AB3:AB121),(AV3:AV121)) -> 0.0016543848
A134: TOD'S | B134: =COVAR(AL3:AL121,C3:C121) -> 0.0020480484 | C134: =COVAR(AL3:AL121,H3:H121) -> 0.0036262587 | D134: =COVAR(AL3:AL121,M3:M121) -> 0.0020916951 | E134: =COVAR(AL3:AL121,R3:R121) -> 0.00080554605 | F134: =COVAR(AL3:AL121,W3:W121) -> 0.00067855125 | G134: =COVAR(AL3:AL121,AG3:AG121) -> -6.0479575e-05 | H134: =COVAR(AL3:AL121,AB3:AB121) -> -0.00055982311 | I134: =COVAR(AL3:AL121,AL3:AL121) -> 0.011320029 | J134: =COVAR(AL3:AL121,AQ3:AQ121) -> 0.0025614883 | K134: =COVAR((AL3:AL121),(AV3:AV121)) -> 0.00015467643
A135: RISO | B135: =COVAR(AQ3:AQ121,C3:C121) -> 0.0016541391 | C135: =COVAR(AQ3:AQ121,H3:H121) -> 0.0019560924 | D135: =COVAR(AQ3:AQ121,M3:M121) -> 0.0017302484 | E135: =COVAR(AQ3:AQ121,R3:R121) -> 0.0011082172 | F135: =COVAR(AQ3:AQ121,W3:W121) -> 0.00088718876 | G135: =COVAR(AQ3:AQ121,AG3:AG121) -> -0.00093026099 | H135: =COVAR(AQ3:AQ121,AB3:AB121) -> -0.00083226071 | I135: =COVAR(AQ3:AQ121,AL3:AL121) -> 0.0025614883 | J135: =COVAR(AQ3:AQ121,AQ3:AQ121) -> 0.0093913834 | K135: =COVAR((AQ3:AQ121),(AV3:AV121)) -> 4.9534916e-05
A136: FIRST SOLAR | B136: =COVAR(AV3:AV121,C3:C121) -> 0.0039002786 | C136: =COVAR(AV3:AV121,H3:H121) -> 0.0013280689 | D136: =COVAR(AV3:AV121,M3:M121) -> 0.0029130318 | E136: =COVAR(AV3:AV121,R3:R121) -> 0.0024817366 | F136: =COVAR(AV3:AV121,W3:W121) -> 0.003476645 | G136: =COVAR(AV3:AV121,AG3:AG121) -> 0.00059807193 | H136: =COVAR(AV3:AV121,AB3:AB121) -> 0.0016543848 | I136: =COVAR(AV3:AV121,AL3:AL121) -> 0.00015467643 | J136: =COVAR(AV3:AV121,AQ3:AQ121) -> 4.9534916e-05 | K136: =COVAR((AV3:AV121),(AV3:AV121)) -> 0.020842491
B139: MATRICE CORRELAZIONE
B141: APPLE | C141: CUCINELLI | D141: GOLDMAN SACHS | E141: JP MORGAN | F141: MICROSOFT | G141: PFIZER | H141: AMERICAN WATER | I141: TOD'S | J141: RISO | K141: FIRST SOLAR
A142: APPLE | B142: =CORREL(C3:C121,C3:C121) -> 1 | C142: =CORREL(H3:H121,C3:C121) -> 0.37420729 | D142: =CORREL(M3:M121,C3:C121) -> 0.43010108 | E142: =CORREL(R3:R121,C3:C121) -> 0.26971217 | F142: =CORREL(W3:W121,C3:C121) -> 0.54209666 | G142: =CORREL(AG3:AG121,C3:C121) -> 0.2170151 | H142: =CORREL(AB3:AB121,C3:C121) -> 0.19130062 | I142: =CORREL(AL3:AL121,C3:C121) -> 0.23840475 | J142: =CORREL(AQ3:AQ121,C3:C121) -> 0.21140036 | K142: =CORREL(C3:C121,AV3:AV121) -> 0.33459488
A143: CUCINELLI | B143: =CORREL(H3:H121,C3:C121) -> 0.37420729 | C143: =CORREL(H3:H121,H3:H121) -> 1 | D143: =CORREL(H3:H121,M3:M121) -> 0.34641913 | E143: =CORREL(H3:H121,R3:R121) -> 0.32905322 | F143: =CORREL(H3:H121,W3:W121) -> 0.34575235 | G143: =CORREL(H3:H121,AG3:AG121) -> 0.19978287 | H143: =CORREL(H3:H121,AB3:AB121) -> 0.11607613 | I143: =CORREL(H3:H121,AL3:AL121) -> 0.38193476 | J143: =CORREL(H3:H121,AQ3:AQ121) -> 0.22619279 | K143: =CORREL(H3:H121,AV3:AV121) -> 0.10308606
A144: GOLDMAN SACHS | B144: =CORREL(M3:M121,C3:C121) -> 0.43010108 | C144: =CORREL(M3:M121,H3:H121) -> 0.34641913 | D144: =CORREL(M3:M121,M3:M121) -> 1 | E144: =CORREL(M3:M121,R3:R121) -> 0.83225227 | F144: =CORREL(M3:M121,W3:W121) -> 0.41072516 | G144: =CORREL(M3:M121,AG3:AG121) -> 0.24172462 | H144: =CORREL(M3:M121,AB3:AB121) -> 0.084050881 | I144: =CORREL(M3:M121,AL3:AL121) -> 0.249488 | J144: =CORREL(M3:M121,AQ3:AQ121) -> 0.22657852 | K144: =CORREL(M3:M121,AV3:AV121) -> 0.2560622
A145: JP MORGAN | B145: =CORREL(R3:R121,C3:C121) -> 0.26971217 | C145: =CORREL(R3:R121,H3:H121) -> 0.32905322 | D145: =CORREL(R3:R121,M3:M121) -> 0.83225227 | E145: =CORREL(R3:R121,R3:R121) -> 1 | F145: =CORREL(R3:R121,W3:W121) -> 0.36078458 | G145: =CORREL(R3:R121,AG3:AG121) -> 0.31612609 | H145: =CORREL(R3:R121,AB3:AB121) -> 0.055259984 | I145: =CORREL(R3:R121,AL3:AL121) -> 0.10923902 | J145: =CORREL(R3:R121,AQ3:AQ121) -> 0.1649952 | K145: =CORREL(R3:R121,AV3:AV121) -> 0.24802307
A146: MICROSOFT | B146: =CORREL(W3:W121,C3:C121) -> 0.54209666 | C146: =CORREL(W3:W121,H3:H121) -> 0.34575235 | D146: =CORREL(W3:W121,M3:M121) -> 0.41072516 | E146: =CORREL(W3:W121,R3:R121) -> 0.36078458 | F146: =CORREL(W3:W121,W3:W121) -> 1 | G146: =CORREL(W3:W121,AG3:AG121) -> 0.22122303 | H146: =CORREL(W3:W121,AB3:AB121) -> 0.22869553 | I146: =CORREL(W3:W121,AL3:AL121) -> 0.10448475 | J146: =CORREL(W3:W121,AQ3:AQ121) -> 0.14998412 | K146: =CORREL(W3:W121,AV3:AV121) -> 0.39452958
A147: PFIZER | B147: =CORREL(AG3:AG121,C3:C121) -> 0.2170151 | C147: =CORREL(AG3:AG121,H3:H121) -> 0.19978287 | D147: =CORREL(AG3:AG121,M3:M121) -> 0.24172462 | E147: =CORREL(AG3:AG121,R3:R121) -> 0.31612609 | F147: =CORREL(AG3:AG121,W3:W121) -> 0.22122303 | G147: =CORREL(AG3:AG121,AG3:AG121) -> 1 | H147: =CORREL(AG3:AG121,AB3:AB121) -> 0.3745107 | I147: =CORREL(AG3:AG121,AL3:AL121) -> -0.00918369 | J147: =CORREL(AG3:AG121,AQ3:AQ121) -> -0.15508589 | K147: =CORREL(AG3:AG121,AV3:AV121) -> 0.066928467
A148: AMERICAN WATER | B148: =CORREL(AB3:AB121,C3:C121) -> 0.19130062 | C148: =CORREL(AB3:AB121,H3:H121) -> 0.11607613 | D148: =CORREL(AB3:AB121,M3:M121) -> 0.084050881 | E148: =CORREL(AB3:AB121,R3:R121) -> 0.055259984 | F148: =CORREL(AB3:AB121,W3:W121) -> 0.22869553 | G148: =CORREL(AB3:AB121,AG3:AG121) -> 0.3745107 | H148: =CORREL(AB3:AB121,AB3:AB121) -> 1 | I148: =CORREL(AB3:AB121,AL3:AL121) -> -0.09784451 | J148: =CORREL(AB3:AB121,AQ3:AQ121) -> -0.15969967 | K148: =CORREL(AB3:AB121,AV3:AV121) -> 0.21309396
A149: TOD'S | B149: =CORREL(AL3:AL121,C3:C121) -> 0.23840475 | C149: =CORREL(AL3:AL121,H3:H121) -> 0.38193476 | D149: =CORREL(AL3:AL121,M3:M121) -> 0.249488 | E149: =CORREL(AL3:AL121,R3:R121) -> 0.10923902 | F149: =CORREL(AL3:AL121,W3:W121) -> 0.10448475 | G149: =CORREL(AL3:AL121,AG3:AG121) -> -0.00918369 | H149: =CORREL(AL3:AL121,AB3:AB121) -> -0.09784451 | I149: =CORREL(AL3:AL121,AL3:AL121) -> 1 | J149: =CORREL(AL3:AL121,AQ3:AQ121) -> 0.24842987 | K149: =CORREL(AL3:AL121,AV3:AV121) -> 0.010069909
A150: RISO | B150: =CORREL(AQ3:AQ121,C3:C121) -> 0.21140036 | C150: =CORREL(AQ3:AQ121,H3:H121) -> 0.22619279 | D150: =CORREL(AQ3:AQ121,M3:M121) -> 0.22657852 | E150: =CORREL(AQ3:AQ121,R3:R121) -> 0.1649952 | F150: =CORREL(AQ3:AQ121,W3:W121) -> 0.14998412 | G150: =CORREL(AQ3:AQ121,AG3:AG121) -> -0.15508589 | H150: =CORREL(AQ3:AQ121,AB3:AB121) -> -0.15969967 | I150: =CORREL(AQ3:AQ121,AL3:AL121) -> 0.24842987 | J150: =CORREL(AQ3:AQ121,AQ3:AQ121) -> 1 | K150: =CORREL(AQ3:AQ121,AV3:AV121) -> 0.003540559
...

Sheet A2-risolutore
B2: Rendimento atteso FIRST SOLAR | C2: 0.02162117
B3: Rendimento atteso AMERICAN WATER | C3: 0.014317676
B4: Rendimento atteso PFIZER | C4: 0.0088334803
B5: Rendimento atteso TOD'S | C5: -0.001530935
B6: Rendimento atteso RISO | C6: 0.013109003
E7: MATRICE VARIANZA COVARIANZA
F8: FIRST SOLAR | G8: AMERICAN WATER | H8: PFIZER | I8: TOD'S | J8: RISO
B9: Varianza FIRST SOLAR | C9: 0.020842491 | E9: FIRST SOLAR | F9: 0.020842491 | G9: 0.0016543848 | H9: 0.00059807193 | I9: 0.00015467643 | J9: 4.9534916e-05
B10: Varianza AMERICAN WATER | C10: 0.0028918859 | E10: AMERICAN WATER | F10: 0.0016543848 | G10: 0.0028918859 | H10: 0.0012465869 | I10: -0.00055982311 | J10: -0.00083226071
B11: Varianza PFIZER | C11: 0.0038312057 | E11: PFIZER | F11: 0.00059807193 | G11: 0.0012465869 | H11: 0.0038312057 | I11: -6.0479575e-05 | J11: -0.00093026099
B12: Varianza TOD'S | C12: 0.011320029 | E12: TOD'S | F12: 0.00015467643 | G12: -0.00055982311 | H12: -6.0479575e-05 | I12: 0.011320029 | J12: 0.0025614883
B13: Varianza RISO | C13: 0.0093913834 | E13: RISO | F13: 4.9534916e-05 | G13: -0.00083226071 | H13: -0.00093026099 | I13: 0.0025614883 | J13: 0.0093913834
B15: Deviazione Standard FIRST SOLAR | C15: =SQRT(C9) -> 0.14436929 | E15: PESI | F15: FIRST SOLAR | G15: AMERICAN WATER | H15: PFIZER | I15: TOD'S | J15: RISO
B16: Deviazione Standard AMERICAN WATER | C16: =SQRT(C10) -> 0.053776258 | F16: -0.1864359 | G16: -0.12892672 | H16: 0.71628838 | I16: 0.67177144 | J16: -0.072697177 | K16: =SUM(F16:J16) -> 1
B17: Deviazione standard PFIZER | C17: =SQRT(C11) -> 0.061896734
B18: Deviazione standard TOD'S | C18: =SQRT(C12) -> 0.10639563 | E18: RENDIMENTO ATTESO DEL PORTAFOGLIO | F18: =F16*C2+G16*C3+H16*C4+C5*I16+C6*J16 -> -0.0015309999
B19: Deviazione Standard RISO | C19: =SQRT(C13) -> 0.09690915
E20: VARIANZA DEL PORTAFOGLIO | F20: {=MMULT(MMULT(F16:J16,F9:J13),TRANSPOSE(F16:J16))} -> 0.0074183098
E22: DEVIAZIONE STANDARD | F22: =SQRT(F20) -> 0.08612961
B24: Rendimento richiesto | C24: -0.001531
F26: PESI
B27: RENDIMENTO ATTESO | C27: VARIANZA | D27: DEVIAZIONE STANDARD | F27: FIRST SOLAR | G27: AMERICAN WATER | H27: PFIZER | I27: TOD'S | J27: RISO | L27: rendimento vincolo
A28: 1 | B28: -0.004425 | C28: 0.010478226 | D28: 0.1023632 | F28: -0.23436311 | G28: -0.2546773 | H28: 0.81873542 | I28: 0.8012822 | J28: -0.13097721 | L28: -0.004425
A29: 2 | B29: -0.001531 | C29: 0.0074183095 | D29: 0.086129609 | F29: -0.18643587 | G29: -0.12892651 | H29: 0.71628797 | I29: 0.67177158 | J29: -0.072697169 | L29: -0.001531
A30: 3 | B30: 0.001363 | C30: 0.0049839194 | D30: 0.07059688 | F30: -0.1385087 | G30: -0.0031757979 | H30: 0.61384074 | I30: 0.54226086 | J30: -0.014417098 | L30: 0.001363
A31: 4 | B31: 0.004257 | C31: 0.0031750553 | D31: 0.056347629 | F31: -0.090581606 | G31: 0.12257489 | H31: 0.51139326 | I31: 0.41275016 | J31: 0.043863298 | L31: 0.004257
A32: 5 | B32: 0.007151 | C32: 0.0019917171 | D32: 0.044628658 | F32: -0.042654297 | G32: 0.24832551 | H32: 0.40894586 | I32: 0.28323955 | J32: 0.10214337 | L32: 0.007151
A33: 6 | B33: 0.010045 | C33: 0.0014339049 | D33: 0.037866937 | F33: 0.0052728882 | G33: 0.37407621 | H33: 0.30649853 | I33: 0.15372886 | J33: 0.16042351 | L33: 0.010045
A34: 7 | B34: 0.012939 | C34: 0.0015016187 | D34: 0.038750725 | F34: 0.053200056 | G34: 0.4998269 | H34: 0.20405117 | I34: 0.02421817 | J34: 0.2187037 | L34: 0.012939
A35: 8 | B35: 0.015833011 | C35: 0.0021948623 | D35: 0.046849358 | F35: 0.10112746 | G35: 0.62557803 | H35: 0.10160342 | I35: -0.10529301 | J35: 0.2769841 | L35: 0.015833
A36: 9 | B36: 0.021621011 | C36: 0.0054579245 | D36: 0.073877767 | F36: 0.19698184 | G36: 0.87707931 | H36: -0.10329122 | I36: -0.3643144 | J36: 0.39354447 | L36: 0.021621
A37: 10 | B37: 0.024515011 | C37: 0.0080277445 | D37: 0.089597681 | F37: 0.244909 | G37: 1.00283 | H37: -0.20573853 | I37: -0.49382511 | J37: 0.45182467 | L37: 0.024515
B40: Varianza richiesta | C40: 0.0021948623
B43: RENDIMENTO ATTESO | C43: VARIANZA | D43: DEVIAZIONE STANDARD | E43: PESI | F43: FIRST SOLAR | G43: AMERICAN WATER | H43: PFIZER | I43: TOD'S | J43: RISO | L43: varianza richiesta
B44: 0.011178722 | C44: 0.0013859061 | D44: 0.03722776 | F44: 0.024048306 | G44: 0.42333873 | H44: 0.26636518 | I44: 0.10299307 | J44: 0.18325475 | L44: 0.0013859061
B45: 0.012939001 | C45: 0.0015016192 | D45: 0.038750731 | F45: 0.053167874 | G45: 0.49986283 | H45: 0.20421867 | I45: 0.024153434 | J45: 0.21859719 | L45: 0.0015016187
B46: 0.015833016 | C46: 0.0021948641 | D46: 0.046849377 | F46: 0.10112561 | G46: 0.62558008 | H46: 0.1017116 | I46: -0.10532583 | J46: 0.27690855 | L46: 0.0021948623

Sheet A2-derivazione analitica
B2: Rendimento atteso FIRST SOLAR | C2: 0.02162117
B3: Rendimento atteso AMERICAN WATER | C3: 0.014317676
B4: Rendimento atteso PFIZER | C4: 0.0088334803
B5: Rendimento atteso TOD'S | C5: -0.001530935
B6: Rendimento atteso RISO | C6: 0.013109003
E7: MATRICE VARIANZA COVARIANZA
F8: FIRST SOLAR | G8: AMERICAN WATER | H8: PFIZER | I8: TOD'S | J8: RISO
B9: Varianza FIRST SOLAR | C9: 0.020842491 | E9: FIRST SOLAR | F9: 0.020842491 | G9: 0.0016543848 | H9: 0.00059807193 | I9: 0.00015467643 | J9: 4.9534916e-05
B10: Varianza AMERICAN WATER | C10: 0.0028918859 | E10: AMERICAN WATER | F10: 0.0016543848 | G10: 0.0028918859 | H10: 0.0012465869 | I10: -0.00055982311 | J10: -0.00083226071
B11: Varianza PFIZER | C11: 0.0038312057 | E11: PFIZER | F11: 0.00059807193 | G11: 0.0012465869 | H11: 0.0038312057 | I11: -6.0479575e-05 | J11: -0.00093026099
B12: Varianza TOD'S | C12: 0.011320029 | E12: TOD'S | F12: 0.00015467643 | G12: -0.00055982311 | H12: -6.0479575e-05 | I12: 0.011320029 | J12: 0.0025614883
B13: Varianza RISO | C13: 0.0093913834 | E13: RISO | F13: 4.9534916e-05 | G13: -0.00083226071 | H13: -0.00093026099 | I13: 0.0025614883 | J13: 0.0093913834
B15: Deviazione Standard FIRST SOLAR | C15: =SQRT(C9) -> 0.14436929
B16: Deviazione Standard AMERICAN WATER | C16: =SQRT(C10) -> 0.053776258
B17: Deviazione standard PFIZER | C17: =SQRT(C11) -> 0.061896734
B18: Deviazione standard TOD'S | C18: =SQRT(C12) -> 0.10639563
B19: Deviazione Standard RISO | C19: =SQRT(C13) -> 0.09690915
B23: DATI UTILI PER CALCOLARE LA FRONTIERA
B25: Vettore 1 | C25: 1 | E25: Vettore 1 (trasposto) | F25: {=TRANSPOSE(C25:C29)} -> 1 | G25: 1 | H25: 1 | I25: 1 | J25: 1
C26: 1
C27: 1
C28: 1
C29: 1
B31: z (vettore dei rendimenti attesi) | C31: 0.02162117 | E31: z' (vettore dei rendimenti trasposto) | F31: {=TRANSPOSE(C31:C35)} -> 0.02162117 | G31: 0.014317676 | H31: 0.0088334803 | I31: -0.001530935 | J31: 0.013109003
C32: 0.014317676
C33: 0.0088334803
C34: -0.001530935
C35: 0.013109003
B37: matrice varianza covarianza | C37: {=MINVERSE(F9:J13)} -> 50.371555 | D37: -30.438341 | E37: 1.438999 | F37: -1.649452 | G37: -2.3706932
C38: -30.438341 | D38: 428.04083 | E38: -129.19653 | F38: 16.167994 | G38: 20.886029
C39: 1.438999 | D39: -129.19653 | E39: 307.93976 | F39: -9.6702729 | G39: 21.683511
C40: -1.649452 | D40: 16.167994 | E40: -9.6702729 | F40: 94.854161 | G40: -25.387741
C41: -2.3706932 | D41: 20.886029 | E41: 21.683511 | F41: -25.387741 | G41: 117.41633
B43: C | C43: {=MMULT(MMULT((F25:J25),(C37:G41)),(C25:C29))} -> 721.54965
B44: A | C44: {=MMULT(MMULT((F25:J25),(C37:G41)),(C31:C35))} -> 8.0660028
B45: B | C45: {=MMULT(MMULT((F31:J31),(C37:G41)),(C31:C35))} -> 0.11694582
B46: D | C46: =(C45*C43)-(C44*C44) -> 19.321815
D48: EP | E48: PESI | F48: FIRST SOLAR | G48: AMERICAN WATER | H48: PFIZER | I48: TOD'S | J48: RISO | K48: TOTALE | M48: rendimento vincolo
A49: G | B49: FIRST SOLAR | C49: {=(MMULT(MMULT((C37:G41),(C25:C29)),C45)-MMULT(MMULT((C37:G41),(C31:C35)),C44))/C46} -> -0.16108112 | D49: 0.024515 | F49: =C49+D49*C55 -> 0.24490882 | G49: =C50+C56*D49 -> 1.0028297 | H49: =C51+C57*D49 -> -0.20573854 | I49: =C52+C58*D49 -> -0.49382447 | J49: =C53+C59*D49 -> 0.45182453 | K49: =SUM(F49:J49) -> 1 | M49: -0.004425 | N49: 1
B50: AMERICAN WATER | C50: -0.06240139 | M50: -0.001531 | N50: 2
...

Sheet A3
B2: Rendimento atteso FIRST SOLAR | C2: 0.02162117
B3: Rendimento atteso AMERICAN WATER | C3: 0.014317676
B4: Rendimento atteso PFIZER | C4: 0.0088334803
B5: Rendimento atteso TOD'S | C5: -0.001530935
B6: Rendimento atteso RISO | C6: 0.013109003
E7: MATRICE VARIANZA COVARIANZA
F8: FIRST SOLAR | G8: AMERICAN WATER | H8: PFIZER | I8: TOD'S | J8: RISO
B9: Varianza FIRST SOLAR | C9: 0.020842491 | E9: FIRST SOLAR | F9: 0.020842491 | G9: 0.0016543848 | H9: 0.00059807193 | I9: 0.00015467643 | J9: 4.9534916e-05
B10: Varianza AMERICAN WATER | C10: 0.0028918859 | E10: AMERICAN WATER | F10: 0.0016543848 | G10: 0.0028918859 | H10: 0.0012465869 | I10: -0.00055982311 | J10: -0.00083226071
B11: Varianza PFIZER | C11: 0.0038312057 | E11: PFIZER | F11: 0.00059807193 | G11: 0.0012465869 | H11: 0.0038312057 | I11: -6.0479575e-05 | J11: -0.00093026099
B12: Varianza TOD'S | C12: 0.011320029 | E12: TOD'S | F12: 0.00015467643 | G12: -0.00055982311 | H12: -6.0479575e-05 | I12: 0.011320029 | J12: 0.0025614883
B13: Varianza RISO | C13: 0.0093913834 | E13: RISO | F13: 4.9534916e-05 | G13: -0.00083226071 | H13: -0.00093026099 | I13: 0.0025614883 | J13: 0.0093913834
B15: Deviazione Standard FIRST SOLAR | C15: =SQRT(C9) -> 0.14436929 | E15: PESI | F15: FIRST SOLAR | G15: AMERICAN WATER | H15: PFIZER | I15: TOD'S | J15: RISO
B16: Deviazione Standard AMERICAN WATER | C16: =SQRT(C10) -> 0.053776258 | F16: 0.10805417 | G16: 0.63359426 | H16: 0.028156175 | I16: 0 | J16: 0.23019539 | K16: =SUM(F16:J16) -> 1
B17: Deviazione standard PFIZER | C17: =SQRT(C11) -> 0.061896734
B18: Deviazione standard TOD'S | C18: =SQRT(C12) -> 0.10639563 | E18: RENDIMENTO ATTESO DEL PORTAFOGLIO | F18: =F16*C2+G16*C3+C4*H16+C5*I16+C6*J16 -> 0.014674204
B19: Deviazione Standard RISO | C19: =SQRT(C13) -> 0.09690915
E20: VARIANZA DEL PORTAFOGLIO | F20: {=MMULT(MMULT(F16:J16,F9:J13),TRANSPOSE(F16:J16))} -> 0.0019272374
E22: DEVIAZIONE STANDARD | F22: =SQRT(F20) -> 0.043900312
B24: Rendimento richiesto | C24: -0.001531
F26: PESI
B27: RENDIMENTO ATTESO | C27: VARIANZA | D27: DEVIAZIONE STANDARD | F27: FIRST SOLAR | G27: AMERICAN WATER | H27: PFIZER | I27: TOD'S | J27: RISO | L27: rendimento vincolo
A28: 1 | B28: -0.001531 | C28: 0.011320039 | D28: =SQRT(C28) -> 0.10639567 | F28: 0 | G28: -2e-07 | H28: -2e-07 | I28: 1.0000004 | J28: 0 | L28: -0.001531
A29: 2 | B29: 0.00078419997 | C29: 0.0069978382 | D29: =SQRT(C29) -> 0.083653083 | F29: 0 | G29: -2e-07 | H29: 0.22337373 | I29: 0.77662647 | J29: 0 | L29: 0.0007842 | N29: 0.0023152
A30: 3 | B30: 0.0030991999 | C30: 0.0041998011 | D30: =SQRT(C30) -> 0.064805873 | F30: 0 | G30: -2e-07 | H30: 0.44673414 | I30: 0.55326606 | J30: 0 | L30: 0.0030992
A31: 4 | B31: 0.0054142006 | C31: 0.0027465292 | D31: =SQRT(C31) -> 0.052407339 | F31: 0 | G31: 0.077231272 | H31: 0.49140623 | I31: 0.38846693 | J31: 0.042895611 | L31: 0.0054142
A32: 5 | B32: 0.0077292 | C32: 0.0018559467 | D32: =SQRT(C32) -> 0.0430807 | F32: 0 | G32: 0.22915764 | H32: 0.39819396 | I32: 0.27010308 | J32: 0.10254532 | L32: 0.0077292
A33: 6 | B33: 0.0100442 | C33: 0.0014339727 | D33: =SQRT(C33) -> 0.037867832 | F33: 0.0052593898 | G33: 0.37404195 | H33: 0.30652631 | I33: 0.15376471 | J33: 0.16040764 | L33: 0.0100442
A34: 7 | B34: 0.0123592 | C34: 0.0014379456 | D34: =SQRT(C34) -> 0.037920254 | F34: 0.043598057 | G34: 0.47463332 | H34: 0.22457604 | I34: 0.050165058 | J34: 0.20702752 | L34: 0.0123592
A35: 8 | B35: 0.0146742 | C35: 0.0019272351 | D35: =SQRT(C35) -> 0.043900286 | F35: 0.10805449 | G35: 0.63376494 | H35: 0.028205976 | I35: 0 | J35: 0.22997459 | L35: 0.0146742
A36: 9 | B36: 0.016989 | C36: 0.0044774345 | D36: =SQRT(C36) -> 0.066913635 | F36: 0.38662407 | G36: 0.48730178 | H36: 0 | I36: 0 | J36: 0.12607415 | L36: 0.016989
A37: 10 | B37: 0.021621017 | C37: 0.020841688 | D37: =SQRT(C37) -> 0.1443665 | F37: 0.99997907 | G37: 2.0918565e-05 | H37: 0 | I37: 0 | J37: 0 | L37: 0.021621
B39: Varianza richiesta | C39: 0.0019272351
B41: Rendimento atteso | C41: varianza | D41: deviazione standard | E41: PESI | F41: FIRST SOLAR | G41: AMERICAN WATER | H41: PFIZER | I41: TOD'S | J41: RISO | L41: varianza richiesta
B42: 0.011178721 | C42: 0.001385906 | D42: 0.037227759 | F42: 0.024048266 | G42: 0.4233389 | H42: 0.26636486 | I42: 0.10299318 | J42: 0.1832548 | L42: 0.0013859061
B43: 0.012939008 | C43: 0.0015016197 | D43: 0.038750739 | F43: 0.053203672 | G43: 0.49991876 | H43: 0.20394162 | I43: 0.024259327 | J43: 0.21867663 | L43: 0.0015016187
B44: 0.014674204 | C44: 0.0019272374 | D44: 0.043900312 | F44: 0.10805417 | G44: 0.63359426 | H44: 0.028156175 | I44: 0 | J44: 0.23019539 | L44: 0.0019272351

Sheet A4-short selling ammesso
O1: INDICE NASDAQ
B2: Rendimento atteso FIRST SOLAR | C2: 0.02162117 | O2: Date | P2: Adj Close | R2: Rendimento atteso | S2: Varianza | T2: Deviazione standard
B3: Rendimento atteso AMERICAN WATER | C3: 0.014317676 | O3: 41395 | P3: 2981760010 | Q3: =(P4-P3)/P3 -> -0.024200443 | R3: =AVERAGE(Q3:Q121) -> 0.013788845 | S3: =COVAR(Q3:Q121,Q3:Q121) -> 0.0027003722 | T3: =SQRT(S3) -> 0.051965105
B4: Rendimento atteso PFIZER | C4: 0.0088334803 | O4: 41426 | P4: 2909600098 | Q4: =(P5-P4)/P4 -> 0.062066895
B5: Rendimento atteso TOD'S | C5: -0.001530935 | O5: 41456 | P5: 3090189941 | Q5: =(P6-P5)/P5 -> -0.0053006069
B6: Rendimento atteso RISO | C6: 0.013109003 | O6: 41487 | P6: 3073810059 | Q6: =(P7-P6)/P6 -> 0.04697424
E7: MATRICE VARIANZA COVARIANZA | O7: 41518 | P7: 3218199951 | Q7: =(P8-P7)/P7 -> 0.049571199
F8: FIRST SOLAR | G8: AMERICAN WATER | H8: PFIZER | I8: TOD'S | J8: RISO | O8: 41548 | P8: 3377729980 | Q8: =(P9-P8)/P8 -> 0.032592921
B9: Varianza FIRST SOLAR | C9: 0.020842491 | E9: FIRST SOLAR | F9: 0.020842491 | G9: 0.0016543848 | H9: 0.00059807193 | I9: 0.00015467643 | J9: 4.9534916e-05 | O9: 41579 | P9: 3487820068 | Q9: =(P10-P9)/P9 -> 0.029869641
B10: Varianza AMERICAN WATER | C10: 0.0028918859 | E10: AMERICAN WATER | F10: 0.0016543848 | G10: 0.0028918859 | H10: 0.0012465869 | I10: -0.00055982311 | J10: -0.00083226071 | O10: 41609 | P10: 3592000000 | Q10: =(P11-P10)/P10 -> -0.019510044
B11: Varianza PFIZER | C11: 0.0038312057 | E11: PFIZER | F11: 0.00059807193 | G11: 0.0012465869 | H11: 0.0038312057 | I11: -6.0479575e-05 | J11: -0.00093026099 | O11: 41640 | P11: 3521919922 | Q11: =(P12-P11)/P11 -> 0.04945603
B12: Varianza TOD'S | C12: 0.011320029 | E12: TOD'S | F12: 0.00015467643 | G12: -0.00055982311 | H12: -6.0479575e-05 | I12: 0.011320029 | J12: 0.0025614883 | O12: 41671 | P12: 3696100098 | Q12: =(P13-P12)/P12 -> -0.027152973
B13: Varianza RISO | C13: 0.0093913834 | E13: RISO | F13: 4.9534916e-05 | G13: -0.00083226071 | H13: -0.00093026099 | I13: 0.0025614883 | J13: 0.0093913834 | O13: 41699 | P13: 3595739990 | Q13: =(P14-P13)/P13 -> -0.0038156179
O14: 41730 | P14: 3582020020 | Q14: =(P15-P14)/P14 -> 0.043215852
B15: Deviazione Standard FIRST SOLAR | C15: =SQRT(C9) -> 0.14436929 | E15: PESI | F15: FIRST SOLAR | G15: AMERICAN WATER | H15: PFIZER | I15: TOD'S | J15: RISO | O15: 41760 | P15: 3736820068 | Q15: =(P16-P15)/P15 -> 0.030148605
B16: Deviazione Standard AMERICAN WATER | C16: =SQRT(C10) -> 0.053776258 | F16: 0.10112561 | G16: 0.62558008 | H16: 0.1017116 | I16: -0.10532583 | J16: 0.27690855 | K16: =SUM(F16:J16) -> 1 | O16: 41791 | P16: 3849479980 | Q16: =(P17-P16)/P16 -> 0.011175541
B17: Deviazione standard PFIZER | C17: =SQRT(C11) -> 0.061896734 | O17: 41821 | P17: 3892500000 | Q17: =(P18-P17)/P17 -> 0.048827247
B18: Deviazione standard TOD'S | C18: =SQRT(C12) -> 0.10639563 | E18: RENDIMENTO ATTESO DEL PORTAFOGLIO | F18: =F16*C2+G16*C3+H16*C4+C5*I16+C6*J16 -> 0.015833016 | O18: 41852 | P18: 4082560059 | Q18: =(P19-P18)/P18 -> -0.0081101337
B19: Deviazione Standard RISO | C19: =SQRT(C13) -> 0.09690915 | O19: 41883 | P19: 4049449951 | Q19: =(P20-P19)/P19 -> 0.026857971
E20: VARIANZA DEL PORTAFOGLIO | F20: {=MMULT(MMULT(F16:J16,F9:J13),TRANSPOSE(F16:J16))} -> 0.0021948641 | O20: 41913 | P20: 4158209961 | Q20: =(P21-P20)/P20 -> 0.043186871
O21: 41944 | P21: 4337790039 | Q21: =(P22-P21)/P21 -> -0.023401376
E22: DEVIAZIONE STANDARD | F22: =SQRT(F20) -> 0.046849377 | O22: 41974 | P22: 4236279785 | Q22: =(P23-P22)/P22 -> -0.020737443
O23: 42005 | P23: 4148430176 | Q23: =(P24-P23)/P23 -> 0.070445864
B24: Rendimento richiesto | C24: 0.024515 | O24: 42036 | P24: 4440669922 | Q24: =(P25-P24)/P24 -> -0.024090955
O25: 42064 | P25: 4333689941 | Q25: =(P26-P25)/P25 -> 0.018589253
F26: PESI | O26: 42095 | P26: 4414250000 | Q26: =(P27-P26)/P26 -> 0.021294671
B27: RENDIMENTO ATTESO | C27: VARIANZA | D27: DEVIAZIONE STANDARD | F27: FIRST SOLAR | G27: AMERICAN WATER | H27: PFIZER | I27: TOD'S | J27: RISO | L27: rendimento vincolo | O27: 42125 | P27: 4508250000 | Q27: =(P28-P27)/P27 -> -0.024730269
A28: 1 | B28: -0.004425 | C28: 0.010478226 | D28: 0.1023632 | F28: -0.23436311 | G28: -0.2546773 | H28: 0.81873542 | I28: 0.8012822 | J28: -0.13097721 | L28: -0.004425 | O28: 42156 | P28: 4396759766 | Q28: =(P29-P28)/P28 -> 0.043702727
A29: 2 | B29: -0.001531 | C29: 0.0074183095 | D29: 0.086129609 | F29: -0.18643587 | G29: -0.12892651 | H29: 0.71628797 | I29: 0.67177158 | J29: -0.072697169 | L29: -0.001531 | O29: 42186 | P29: 4588910156 | Q29: =(P30-P29)/P29 -> -0.068497763
A30: 3 | B30: 0.001363 | C30: 0.0049839194 | D30: 0.07059688 | F30: -0.1385087 | G30: -0.0031757979 | H30: 0.61384074 | I30: 0.54226086 | J30: -0.014417098 | L30: 0.001363 | O30: 42217 | P30: 4274580078 | Q30: =(P31-P30)/P30 -> -0.021878177
A31: 4 | B31: 0.004257 | C31: 0.0031750553 | D31: 0.056347629 | F31: -0.090581606 | G31: 0.12257489 | H31: 0.51139326 | I31: 0.41275016 | J31: 0.043863298 | L31: 0.004257 | O31: 42248 | P31: 4181060059 | Q31: =(P32-P31)/P31 -> 0.11187833
A32: 5 | B32: 0.007151 | C32: 0.0019917171 | D32: 0.044628658 | F32: -0.042654297 | G32: 0.24832551 | H32: 0.40894586 | I32: 0.28323955 | J32: 0.10214337 | L32: 0.007151 | O32: 42278 | P32: 4648830078 | Q32: =(P33-P32)/P32 -> 0.0033728245
A33: 6 | B33: 0.010045 | C33: 0.0014339049 | D33: 0.037866937 | F33: 0.0052728882 | G33: 0.37407621 | H33: 0.30649853 | I33: 0.15372886 | J33: 0.16042351 | L33: 0.010045 | O33: 42309 | P33: 4664509766 | Q33: =(P34-P33)/P33 -> -0.015272719
A34: 7 | B34: 0.012939 | C34: 0.0015016187 | D34: 0.038750725 | F34: 0.053200056 | G34: 0.4998269 | H34: 0.20405117 | I34: 0.02421817 | J34: 0.2187037 | L34: 0.012939 | O34: 42339 | P34: 4593270020 | Q34: =(P35-P34)/P34 -> -0.068382677
A35: 8 | B35: 0.015833011 | C35: 0.0021948623 | D35: 0.046849358 | F35: 0.10112746 | G35: 0.62557803 | H35: 0.10160342 | I35: -0.10529301 | J35: 0.2769841 | L35: 0.015833 | O35: 42370 | P35: 4279169922 | Q35: =(P36-P35)/P35 -> -0.018239473
A36: 9 | B36: 0.021621011 | C36: 0.0054579245 | D36: 0.073877767 | F36: 0.19698184 | G36: 0.87707931 | H36: -0.10329122 | I36: -0.3643144 | J36: 0.39354447 | L36: 0.021621 | O36: 42401 | P36: 4201120117 | Q36: =(P37-P36)/P36 -> 0.067253502
A37: 10 | B37: 0.024515011 | C37: 0.0080277445 | D37: 0.089597681 | F37: 0.244909 | G37: 1.00283 | H37: -0.20573853 | I37: -0.49382511 | J37: 0.45182467 | L37: 0.024515 | O37: 42430 | P37: 4483660156 | Q37: =(P38-P37)/P37 -> -0.031750924
O38: 42461 | P38: 4341299805 | Q38: =(P39-P38)/P38 -> 0.042058909
O39: 42491 | P39: 4523890137 | Q39: =(P40-P39)/P39 -> -0.023473148
B40: Varianza richiesta | C40: 0.0021948623 | O40: 42522 | P40: 4417700195 | Q40: =(P41-P40)/P40 -> 0.070744906
...

Sheet A4-short selling non ammesso
B2: Rendimento atteso FIRST SOLAR | C2: 0.02162117
B3: Rendimento atteso AMERICAN WATER | C3: 0.014317676
B4: Rendimento atteso PFIZER | C4: 0.0088334803
B5: Rendimento atteso TOD'S | C5: -0.001530935
B6: Rendimento atteso RISO | C6: 0.013109003
E7: MATRICE VARIANZA COVARIANZA
F8: FIRST SOLAR | G8: AMERICAN WATER | H8: PFIZER | I8: TOD'S | J8: RISO
B9: Varianza FIRST SOLAR | C9: 0.020842491 | E9: FIRST SOLAR | F9: 0.020842491 | G9: 0.0016543848 | H9: 0.00059807193 | I9: 0.00015467643 | J9: 4.9534916e-05
B10: Varianza AMERICAN WATER | C10: 0.0028918859 | E10: AMERICAN WATER | F10: 0.0016543848 | G10: 0.0028918859 | H10: 0.0012465869 | I10: -0.00055982311 | J10: -0.00083226071
B11: Varianza PFIZER | C11: 0.0038312057 | E11: PFIZER | F11: 0.00059807193 | G11: 0.0012465869 | H11: 0.0038312057 | I11: -6.0479575e-05 | J11: -0.00093026099
B12: Varianza TOD'S | C12: 0.011320029 | E12: TOD'S | F12: 0.00015467643 | G12: -0.00055982311 | H12: -6.0479575e-05 | I12: 0.011320029 | J12: 0.0025614883
B13: Varianza RISO | C13: 0.0093913834 | E13: RISO | F13: 4.9534916e-05 | G13: -0.00083226071 | H13: -0.00093026099 | I13: 0.0025614883 | J13: 0.0093913834
B15: Deviazione Standard FIRST SOLAR | C15: =SQRT(C9) -> 0.14436929 | E15: PESI | F15: FIRST SOLAR | G15: AMERICAN WATER | H15: PFIZER | I15: TOD'S | J15: RISO
B16: Deviazione Standard AMERICAN WATER | C16: =SQRT(C10) -> 0.053776258 | F16: 0.99997907 | G16: 2.0918565e-05 | H16: 0 | I16: 0 | J16: 0 | K16: =SUM(F16:J16) -> 0.99999999
B17: Deviazione standard PFIZER | C17: =SQRT(C11) -> 0.061896734
B18: Deviazione standard TOD'S | C18: =SQRT(C12) -> 0.10639563 | E18: RENDIMENTO ATTESO DEL PORTAFOGLIO | F18: =F16*C2+G16*C3+C4*H16+C5*I16+C6*J16 -> 0.021621017
B19: Deviazione Standard RISO | C19: =SQRT(C13) -> 0.09690915
E20: VARIANZA DEL PORTAFOGLIO | F20: {=MMULT(MMULT(F16:J16,F9:J13),TRANSPOSE(F16:J16))} -> 0.020841688
E22: DEVIAZIONE STANDARD | F22: =SQRT(F20) -> 0.1443665
B24: Rendimento richiesto | C24: 0.021621
F26: PESI
B27: RENDIMENTO ATTESO | C27: VARIANZA | D27: DEVIAZIONE STANDARD | F27: FIRST SOLAR | G27: AMERICAN WATER | H27: PFIZER | I27: TOD'S | J27: RISO | L27: rendimento vincolo
A28: 1 | B28: -0.001531 | C28: 0.011320039 | D28: =SQRT(C28) -> 0.10639567 | F28: 0 | G28: -2e-07 | H28: -2e-07 | I28: 1.0000004 | J28: 0 | L28: -0.001531
A29: 2 | B29: 0.00078419997 | C29: 0.0069978382 | D29: =SQRT(C29) -> 0.083653083 | F29: 0 | G29: -2e-07 | H29: 0.22337373 | I29: 0.77662647 | J29: 0 | L29: 0.0007842
A30: 3 | B30: 0.0030991999 | C30: 0.0041998011 | D30: =SQRT(C30) -> 0.064805873 | F30: 0 | G30: -2e-07 | H30: 0.44673414 | I30: 0.55326606 | J30: 0 | L30: 0.0030992
A31: 4 | B31: 0.0054142006 | C31: 0.0027465292 | D31: =SQRT(C31) -> 0.052407339 | F31: 0 | G31: 0.077231272 | H31: 0.49140623 | I31: 0.38846693 | J31: 0.042895611 | L31: 0.0054142
A32: 5 | B32: 0.0077292 | C32: 0.0018559467 | D32: =SQRT(C32) -> 0.0430807 | F32: 0 | G32: 0.22915764 | H32: 0.39819396 | I32: 0.27010308 | J32: 0.10254532 | L32: 0.0077292
A33: 6 | B33: 0.0100442 | C33: 0.0014339727 | D33: =SQRT(C33) -> 0.037867832 | F33: 0.0052593898 | G33: 0.37404195 | H33: 0.30652631 | I33: 0.15376471 | J33: 0.16040764 | L33: 0.0100442
A34: 7 | B34: 0.0123592 | C34: 0.0014379456 | D34: =SQRT(C34) -> 0.037920254 | F34: 0.043598057 | G34: 0.47463332 | H34: 0.22457604 | I34: 0.050165058 | J34: 0.20702752 | L34: 0.0123592
A35: 8 | B35: 0.0146742 | C35: 0.0019272351 | D35: =SQRT(C35) -> 0.043900286 | F35: 0.10805449 | G35: 0.63376494 | H35: 0.028205976 | I35: 0 | J35: 0.22997459 | L35: 0.0146742
A36: 9 | B36: 0.016989 | C36: 0.0044774345 | D36: =SQRT(C36) -> 0.066913635 | F36: 0.38662407 | G36: 0.48730178 | H36: 0 | I36: 0 | J36: 0.12607415 | L36: 0.016989
A37: 10 | B37: 0.021621017 | C37: 0.020841688 | D37: =SQRT(C37) -> 0.1443665 | F37: 0.99997907 | G37: 2.0918565e-05 | H37: 0 | I37: 0 | J37: 0 | L37: 0.021621
B40: Rendimento atteso | C40: varianza | D40: deviazione standard | E40: PESI | F40: FIRST SOLAR | G40: AMERICAN WATER | H40: PFIZER | I40: TOD'S | J40: RISO | L40: varianza richiesta
B41: 0.011178721 | C41: 0.001385906 | D41: 0.037227759 | F41: 0.024048266 | G41: 0.4233389 | H41: 0.26636486 | I41: 0.10299318 | J41: 0.1832548 | L41: 0.0013859061
B42: 0.012939008 | C42: 0.0015016197 | D42: 0.038750739 | F42: 0.053203672 | G42: 0.49991876 | H42: 0.20394162 | I42: 0.024259327 | J42: 0.21867663 | L42: 0.0015016187
B43: 0.014674204 | C43: 0.0019272374 | D43: 0.043900312 | F43: 0.10805417 | G43: 0.63359426 | H43: 0.028156175 | I43: 0 | J43: 0.23019539 | L43: 0.0019272351
B46: INDICE NASDAQ
B47: Rendimento atteso | C47: Varianza | D47: Deviazione standard
B48: 0.013788845 | C48: 0.0027003722 | D48: 0.051965105

Sheet A5-EW con 5 titoli
B2: Rendimento atteso FIRST SOLAR | C2: 0.02162117
B3: Rendimento atteso AMERICAN WATER | C3: 0.014317676
B4: Rendimento atteso PFIZER | C4: 0.0088334803
B5: Rendimento atteso TOD'S | C5: -0.001530935
B6: Rendimento atteso RISO | C6: 0.013109003
E7: MATRICE VARIANZA COVARIANZA
F8: FIRST SOLAR | G8: AMERICAN WATER | H8: PFIZER | I8: TOD'S | J8: RISO
B9: Varianza FIRST SOLAR | C9: 0.020842491 | E9: FIRST SOLAR | F9: 0.020842491 | G9: 0.0016543848 | H9: 0.00059807193 | I9: 0.00015467643 | J9: 4.9534916e-05
B10: Varianza AMERICAN WATER | C10: 0.0028918859 | E10: AMERICAN WATER | F10: 0.0016543848 | G10: 0.0028918859 | H10: 0.0012465869 | I10: -0.00055982311 | J10: -0.00083226071
B11: Varianza PFIZER | C11: 0.0038312057 | E11: PFIZER | F11: 0.00059807193 | G11: 0.0012465869 | H11: 0.0038312057 | I11: -6.0479575e-05 | J11: -0.00093026099
B12: Varianza TOD'S | C12: 0.011320029 | E12: TOD'S | F12: 0.00015467643 | G12: -0.00055982311 | H12: -6.0479575e-05 | I12: 0.011320029 | J12: 0.0025614883
B13: Varianza RISO | C13: 0.0093913834 | E13: RISO | F13: 4.9534916e-05 | G13: -0.00083226071 | H13: -0.00093026099 | I13: 0.0025614883 | J13: 0.0093913834
B15: Deviazione Standard FIRST SOLAR | C15: =SQRT(C9) -> 0.14436929 | E15: PESI | F15: FIRST SOLAR | G15: AMERICAN WATER | H15: PFIZER | I15: TOD'S | J15: RISO
B16: Deviazione Standard AMERICAN WATER | C16: =SQRT(C10) -> 0.053776258 | F16: 0.2 | G16: 0.2 | H16: 0.2 | I16: 0.2 | J16: 0.2 | K16: =SUM(F16:J16) -> 1
B17: Deviazione standard PFIZER | C17: =SQRT(C11) -> 0.061896734
B18: Deviazione standard TOD'S | C18: =SQRT(C12) -> 0.10639563 | E18: RENDIMENTO ATTESO DEL PORTAFOGLIO | F18: =F16*C2+G16*C3+H16*C4+C5*I16+C6*J16 -> 0.011270079
B19: Deviazione Standard RISO | C19: =SQRT(C13) -> 0.09690915
E20: VARIANZA DEL PORTAFOGLIO | F20: {=MMULT(MMULT(F16:J16,F9:J13),TRANSPOSE(F16:J16))} -> 0.0022416333
E22: DEVIAZIONE STANDARD | F22: =SQRT(F20) -> 0.04734589
B24: Rendimento richiesto | C24: 0.0021118369
F26: PESI
B27: RENDIMENTO ATTESO | C27: VARIANZA | D27: DEVIAZIONE STANDARD | F27: FIRST SOLAR | G27: AMERICAN WATER | H27: PFIZER | I27: TOD'S | J27: RISO | L27: rendimento vincolo
A28: 1 | B28: -0.004425 | C28: 0.010478226 | D28: 0.1023632 | F28: -0.23436311 | G28: -0.2546773 | H28: 0.81873542 | I28: 0.8012822 | J28: -0.13097721 | L28: -0.004425
A29: 2 | B29: -0.001531 | C29: 0.0074183095 | D29: 0.086129609 | F29: -0.18643587 | G29: -0.12892651 | H29: 0.71628797 | I29: 0.67177158 | J29: -0.072697169 | L29: -0.001531
A30: 3 | B30: 0.001363 | C30: 0.0049839194 | D30: 0.07059688 | F30: -0.1385087 | G30: -0.0031757979 | H30: 0.61384074 | I30: 0.54226086 | J30: -0.014417098 | L30: 0.001363
A31: 4 | B31: 0.004257 | C31: 0.0031750553 | D31: 0.056347629 | F31: -0.090581606 | G31: 0.12257489 | H31: 0.51139326 | I31: 0.41275016 | J31: 0.043863298 | L31: 0.004257
A32: 5 | B32: 0.007151 | C32: 0.0019917171 | D32: 0.044628658 | F32: -0.042654297 | G32: 0.24832551 | H32: 0.40894586 | I32: 0.28323955 | J32: 0.10214337 | L32: 0.007151
A33: 6 | B33: 0.010045 | C33: 0.0014339049 | D33: 0.037866937 | F33: 0.0052728882 | G33: 0.37407621 | H33: 0.30649853 | I33: 0.15372886 | J33: 0.16042351 | L33: 0.010045
A34: 7 | B34: 0.012939 | C34: 0.0015016187 | D34: 0.038750725 | F34: 0.053200056 | G34: 0.4998269 | H34: 0.20405117 | I34: 0.02421817 | J34: 0.2187037 | L34: 0.012939
A35: 8 | B35: 0.015833011 | C35: 0.0021948623 | D35: 0.046849358 | F35: 0.10112746 | G35: 0.62557803 | H35: 0.10160342 | I35: -0.10529301 | J35: 0.2769841 | L35: 0.015833
B36: 0.01596567 | C36: 0.0022416342 | D36: 0.0473459 | F36: 0.10335663 | G36: 0.63124249 | H36: 0.096883875 | I36: -0.11121235 | J36: 0.27972936
A37: 9 | B37: 0.021621011 | C37: 0.0054579245 | D37: 0.073877767 | F37: 0.19698184 | G37: 0.87707931 | H37: -0.10329122 | I37: -0.3643144 | J37: 0.39354447 | L37: 0.021621
A38: 10 | B38: 0.024515011 | C38: 0.0080277445 | D38: 0.089597681 | F38: 0.244909 | G38: 1.00283 | H38: -0.20573853 | I38: -0.49382511 | J38: 0.45182467 | L38: 0.024515
B41: Varianza richiesta | C41: 0.0021118369
B44: RENDIMENTO ATTESO | C44: VARIANZA | D44: DEVIAZIONE STANDARD | E44: PESI | F44: FIRST SOLAR | G44: AMERICAN WATER | H44: PFIZER | I44: TOD'S | J44: RISO | L44: varianza richiesta
B45: 0.011178722 | C45: 0.0013859061 | D45: 0.03722776 | F45: 0.024048306 | G45: 0.42333873 | H45: 0.26636518 | I45: 0.10299307 | J45: 0.18325475 | L45: 0.0013859061
B46: 0.012939001 | C46: 0.0015016192 | D46: 0.038750731 | F46: 0.053167874 | G46: 0.49986283 | H46: 0.20421867 | I46: 0.024153434 | J46: 0.21859719 | L46: 0.0015016187
B47: 0.015833016 | C47: 0.0021948641 | D47: 0.046849377 | F47: 0.10112561 | G47: 0.62558008 | H47: 0.1017116 | I47: -0.10532583 | J47: 0.27690855 | L47: 0.0021948623
B49: INDICE NASDAQ
B50: RENDIMENTO ATTESO | C50: VARIANZA | D50: DEVIAZIONE STANDARD
...

Sheet A5-EW con 10 titoli
B1: MATRICE VARIANZA COVARIANZA
B2: APPLE | C2: CUCINELLI | D2: GOLDMAN SACH | E2: JP MORGAN | F2: MICROSOFT | G2: PFIZER | H2: AMERICAN WATER | I2: TOD'S | J2: RISO | K2: FIRST SOLAR
A3: APPLE | B3: 0.0065193315 | C3: 0.0026962466 | D3: 0.0027365098 | E3: 0.0015093532 | F3: 0.0026716787 | G3: 0.0010845741 | H3: 0.0008306317 | I3: 0.0020480484 | J3: 0.0016541391 | K3: 0.0039002786
A4: CUCINELLI | B4: 0.0026962466 | C4: 0.0079632739 | D4: 0.0024359739 | E4: 0.0020351704 | F4: 0.0018832888 | G4: 0.0011034986 | H4: 0.00055703093 | I4: 0.0036262587 | J4: 0.0019560924 | K4: 0.0013280689
A5: GOLDMAN SACH | B5: 0.0027365098 | C5: 0.0024359739 | D5: 0.0062094035 | E5: 0.0045453646 | F5: 0.0019755235 | G5: 0.0011789993 | H5: 0.00035617037 | I5: 0.0020916951 | J5: 0.0017302484 | K5: 0.0029130318
A6: JP MORGAN | B6: 0.0015093532 | C6: 0.0020351704 | D6: 0.0045453646 | E6: 0.004803719 | F6: 0.0015263099 | G6: 0.0013561786 | H6: 0.00020596344 | I6: 0.00080554605 | J6: 0.0011082172 | K6: 0.0024817366
A7: MICROSOFT | B7: 0.0026716787 | C7: 0.0018832888 | D7: 0.0019755235 | E7: 0.0015263099 | F7: 0.0037257347 | G7: 0.00083580321 | H7: 0.00075067892 | I7: 0.00067855125 | J7: 0.00088718876 | K7: 0.003476645
A8: PFIZER | B8: 0.0010845741 | C8: 0.0011034986 | D8: 0.0011789993 | E8: 0.0013561786 | F8: 0.00083580321 | G8: 0.0038312057 | H8: 0.0012465869 | I8: -6.0479575e-05 | J8: -0.00093026099 | K8: 0.00059807193
A9: AMERICAN WATER | B9: 0.0008306317 | C9: 0.00055703093 | D9: 0.00035617037 | E9: 0.00020596344 | F9: 0.00075067892 | G9: 0.0012465869 | H9: 0.0028918859 | I9: -0.00055982311 | J9: -0.00083226071 | K9: 0.0016543848
A10: TOD'S | B10: 0.0020480484 | C10: 0.0036262587 | D10: 0.0020916951 | E10: 0.00080554605 | F10: 0.00067855125 | G10: -6.0479575e-05 | H10: -0.00055982311 | I10: 0.011320029 | J10: 0.0025614883 | K10: 0.00015467643
A11: RISO | B11: 0.0016541391 | C11: 0.0019560924 | D11: 0.0017302484 | E11: 0.0011082172 | F11: 0.00088718876 | G11: -0.00093026099 | H11: -0.00083226071 | I11: 0.0025614883 | J11: 0.0093913834 | K11: 4.9534916e-05
A12: FIRST SOLAR | B12: 0.0039002786 | C12: 0.0013280689 | D12: 0.0029130318 | E12: 0.0024817366 | F12: 0.003476645 | G12: 0.00059807193 | H12: 0.0016543848 | I12: 0.00015467643 | J12: 4.9534916e-05 | K12: 0.020842491
A14: RENDIMENTI | D14: DEVIAZIONI STANDARD | F14: PESI
A15: APPLE | B15: 0.024266687 | D15: =SQRT(0.00651933151341803) -> 0.080742377 | F15: APPLE | G15: CUCCINELLI | H15: GOLDMAN SACH | I15: JP MORGAN | J15: MICROSOFT | K15: PFIZER | L15: AMERICAN WATER | M15: TOD'S | N15: RISO | O15: FIRST SOLAR | P15: TOTALE
A16: CUCINELLI | B16: 0.018519405 | D16: =SQRT(0.00796327389222818) -> 0.089237178 | F16: 0.1 | G16: 0.1 | H16: 0.1 | I16: 0.1 | J16: 0.1 | K16: 0.1 | L16: 0.1 | M16: 0.1 | N16: 0.1 | O16: 0.1 | P16: =SUM(F16:O16) -> 1
A17: GOLDMAN SACH | B17: 0.010700275 | D17: =SQRT(0.00620940349714009) -> 0.078799768
A18: JP MORGAN | B18: 0.012575794 | D18: 0.004803719 | F18: RENDIMENTO ATTESO DEL PORTAFOGLIO | G18: =F16*B15+G16*B16+H16*B17+I16*B18+J16*B19+K16*B20+L16*B21+M16*B22+N16*B23+O16*B24 -> 0.014367107
A19: MICROSOFT | B19: 0.02125851 | D19: =SQRT(0.00372573470405919) -> 0.061038797
A20: PFIZER | B20: 0.014317676 | D20: =SQRT(0.00383120565045276) -> 0.061896734 | F20: VARIANZA | G20: {=MMULT(MMULT(F16:O16,B3:K12),TRANSPOSE(F16:O16))} -> 0.0021118369
A21: AMERICAN WATER | B21: 0.0088334803 | D21: =SQRT(0.00289188592770238) -> 0.053776258
A22: TOD'S | B22: -0.001530935 | D22: =SQRT(0.0113200294927509) -> 0.10639563 | F22: DEVIAZIONE STANDARD | G22: =SQRT(G20) -> 0.045954726
A23: RISO | B23: 0.013109003 | D23: =SQRT(0.00939138336330571) -> 0.09690915
A24: FIRST SOLAR | B24: 0.02162117 | D24: =SQRT(0.0208424907732386) -> 0.14436929
B27: Rendimento richiesto | C27: 0.0022416333
F29: PESI
B30: RENDIMENTO ATTESO | C30: VARIANZA | D30: DEVIAZIONE STANDARD | F30: FIRST SOLAR | G30: AMERICAN WATER | H30: PFIZER | I30: TOD'S | J30: RISO | L30: rendimento vincolo
A31: 1 | B31: -0.004425 | C31: 0.010478226 | D31: 0.1023632 | F31: -0.23436311 | G31: -0.2546773 | H31: 0.81873542 | I31: 0.8012822 | J31: -0.13097721 | L31: -0.004425
A32: 2 | B32: -0.001531 | C32: 0.0074183095 | D32: 0.086129609 | F32: -0.18643587 | G32: -0.12892651 | H32: 0.71628797 | I32: 0.67177158 | J32: -0.072697169 | L32: -0.001531
A33: 3 | B33: 0.001363 | C33: 0.0049839194 | D33: 0.07059688 | F33: -0.1385087 | G33: -0.0031757979 | H33: 0.61384074 | I33: 0.54226086 | J33: -0.014417098 | L33: 0.001363
A34: 4 | B34: 0.004257 | C34: 0.0031750553 | D34: 0.056347629 | F34: -0.090581606 | G34: 0.12257489 | H34: 0.51139326 | I34: 0.41275016 | J34: 0.043863298 | L34: 0.004257
A35: 5 | B35: 0.007151 | C35: 0.0019917171 | D35: 0.044628658 | F35: -0.042654297 | G35: 0.24832551 | H35: 0.40894586 | I35: 0.28323955 | J35: 0.10214337 | L35: 0.007151
A36: 6 | B36: 0.010045 | C36: 0.0014339049 | D36: 0.037866937 | F36: 0.0052728882 | G36: 0.37407621 | H36: 0.30649853 | I36: 0.15372886 | J36: 0.16042351 | L36: 0.010045
A37: 7 | B37: 0.012939 | C37: 0.0015016187 | D37: 0.038750725 | F37: 0.053200056 | G37: 0.4998269 | H37: 0.20405117 | I37: 0.02421817 | J37: 0.2187037 | L37: 0.012939
B38: 0.015587707 | C38: 0.0021118374 | D38: 0.045954733 | F38: 0.097063052 | G38: 0.61499347 | H38: 0.11022527 | I38: -0.094292205 | J38: 0.27201042
A39: 8 | B39: 0.015833011 | C39: 0.0021948623 | D39: 0.046849358 | F39: 0.10112746 | G39: 0.62557803 | H39: 0.10160342 | I39: -0.10529301 | J39: 0.2769841 | L39: 0.015833
A40: 9 | B40: 0.021621011 | C40: 0.0054579245 | D40: 0.073877767 | F40: 0.19698184 | G40: 0.87707931 | H40: -0.10329122 | I40: -0.3643144 | J40: 0.39354447 | L40: 0.021621
A41: 10 | B41: 0.024515011 | C41: 0.0080277445 | D41: 0.089597681 | F41: 0.244909 | G41: 1.00283 | H41: -0.20573853 | I41: -0.49382511 | J41: 0.45182467 | L41: 0.024515
B44: Varianza richiesta | C44: 0.0021118369
B47: RENDIMENTO ATTESO | C47: VARIANZA | D47: DEVIAZIONE STANDARD | E47: PESI | F47: FIRST SOLAR | G47: AMERICAN WATER | H47: PFIZER | I47: TOD'S | J47: RISO | L47: varianza richiesta
B48: 0.011178722 | C48: 0.0013859061 | D48: 0.03722776 | F48: 0.024048306 | G48: 0.42333873 | H48: 0.26636518 | I48: 0.10299307 | J48: 0.18325475 | L48: 0.0013859061
...

Sheet A6
B2: Rendimento atteso FIRST SOLAR | C2: 0.02162117
B3: Rendimento atteso AMERICAN WATER | C3: 0.014317676
B4: Rendimento atteso PFIZER | C4: 0.0088334803
B5: Rendimento atteso TOD'S | C5: -0.001530935
B6: Rendimento atteso RISO | C6: 0.013109003
E7: MATRICE VARIANZA COVARIANZA
F8: FIRST SOLAR | G8: AMERICAN WATER | H8: PFIZER | I8: TOD'S | J8: RISO
B9: Varianza FIRST SOLAR | C9: 0.020842491 | E9: FIRST SOLAR | F9: 0.020842491 | G9: 0.0016543848 | H9: 0.00059807193 | I9: 0.00015467643 | J9: 4.9534916e-05
B10: Varianza AMERICAN WATER | C10: 0.0028918859 | E10: AMERICAN WATER | F10: 0.0016543848 | G10: 0.0028918859 | H10: 0.0012465869 | I10: -0.00055982311 | J10: -0.00083226071
B11: Varianza PFIZER | C11: 0.0038312057 | E11: PFIZER | F11: 0.00059807193 | G11: 0.0012465869 | H11: 0.0038312057 | I11: -6.0479575e-05 | J11: -0.00093026099
B12: Varianza TOD'S | C12: 0.011320029 | E12: TOD'S | F12: 0.00015467643 | G12: -0.00055982311 | H12: -6.0479575e-05 | I12: 0.011320029 | J12: 0.0025614883
B13: Varianza RISO | C13: 0.0093913834 | E13: RISO | F13: 4.9534916e-05 | G13: -0.00083226071 | H13: -0.00093026099 | I13: 0.0025614883 | J13: 0.0093913834
B15: Deviazione Standard FIRST SOLAR | C15: =SQRT(C9) -> 0.14436929 | E15: PESI | F15: FIRST SOLAR | G15: AMERICAN WATER | H15: PFIZER | I15: TOD'S | J15: RISO
B16: Deviazione Standard AMERICAN WATER | C16: =SQRT(C10) -> 0.053776258 | F16: 0.2 | G16: 0.2 | H16: 0.2 | I16: 0.2 | J16: 0.2 | K16: =SUM(F16:J16) -> 1
B17: Deviazione standard PFIZER | C17: =SQRT(C11) -> 0.061896734
B18: Deviazione standard TOD'S | C18: =SQRT(C12) -> 0.10639563 | E18: RENDIMENTO ATTESO DEL PORTAFOGLIO | F18: =F16*C2+G16*C3+H16*C4+I16*C5+J16*C6 -> 0.011270079 | J18: =(F18-C23)/F22 -> 0.072412032
B19: Deviazione Standard RISO | C19: =SQRT(C13) -> 0.09690915
E20: VARIANZA DEL PORTAFOGLIO | F20: {=MMULT(MMULT(F16:J16,F9:J13),TRANSPOSE(F16:J16))} -> 0.0022416333
E22: DEVIAZIONE STANDARD | F22: =SQRT(F20) -> 0.04734589
B23: Titolo free risk T-BILL USA | C23: =(0.04705*2)/12 -> 0.0078416667
B25: Rendimento richiesto | C25: 0.017
F27: PESI
B28: RENDIMENTO ATTESO | C28: VARIANZA | D28: DEVIAZIONE STANDARD | F28: FIRST SOLAR | G28: AMERICAN WATER | H28: PFIZER | I28: TOD'S | J28: RISO | K28: SHARPE RATIO | L28: rendimento vincolo
A29: 1 | B29: -0.004425 | C29: 0.010478226 | D29: 0.1023632 | F29: -0.23436311 | G29: -0.2546773 | H29: 0.81873542 | I29: 0.8012822 | J29: -0.13097721 | K29: =(B29-C23)/D29 -> -0.11983473 | L29: -0.004425
A30: 2 | B30: -0.001531 | C30: 0.0074183095 | D30: 0.086129609 | F30: -0.18643587 | G30: -0.12892651 | H30: 0.71628797 | I30: 0.67177158 | J30: -0.072697169 | K30: =(B30-C23)/D30 -> -0.1088205 | L30: -0.001531
A31: 3 | B31: 0.001363 | C31: 0.0049839194 | D31: 0.07059688 | F31: -0.1385087 | G31: -0.0031757979 | H31: 0.61384074 | I31: 0.54226086 | J31: -0.014417098 | K31: =(B31-C23)/D31 -> -0.091769873 | L31: 0.001363
A32: 4 | B32: 0.004257 | C32: 0.0031750553 | D32: 0.056347629 | F32: -0.090581606 | G32: 0.12257489 | H32: 0.51139326 | I32: 0.41275016 | J32: 0.043863298 | K32: =(B32-C23)/D32 -> -0.063616992 | L32: 0.004257
A33: 5 | B33: 0.007151 | C33: 0.0019917171 | D33: 0.044628658 | F33: -0.042654297 | G33: 0.24832551 | H33: 0.40894586 | I33: 0.28323955 | J33: 0.10214337 | K33: =(B33-C23)/D33 -> -0.015475856 | L33: 0.007151
A34: 6 | B34: 0.010045 | C34: 0.0014339049 | D34: 0.037866937 | F34: 0.0052728882 | G34: 0.37407621 | H34: 0.30649853 | I34: 0.15372886 | J34: 0.16042351 | K34: =(B34-C23)/D34 -> 0.058186203 | L34: 0.010045
A35: 7 | B35: 0.012939 | C35: 0.0015016187 | D35: 0.038750725 | F35: 0.053200056 | G35: 0.4998269 | H35: 0.20405117 | I35: 0.02421817 | J35: 0.2187037 | K35: =(B35-C23)/D35 -> 0.13154162 | L35: 0.012939
A36: 8 | B36: 0.015833011 | C36: 0.0021948623 | D36: 0.046849358 | F36: 0.10112746 | G36: 0.62557803 | H36: 0.10160342 | I36: -0.10529301 | J36: 0.2769841 | K36: =(B36-C23)/D36 -> 0.17057533 | L36: 0.015833
